2023-04-16 19:13:44,621 - connectionpool.py[line:812] - WARNING: Retrying (Retry(total=2, connect=None, read=None, redirect=None, status=None)) after connection broken by 'NewConnectionError('<urllib3.connection.HTTPConnection object at 0x00000235FC0257E0>: Failed to establish a new connection: [Errno 11001] getaddrinfo failed')': /
2023-04-16 19:13:44,623 - connectionpool.py[line:812] - WARNING: Retrying (Retry(total=1, connect=None, read=None, redirect=None, status=None)) after connection broken by 'NewConnectionError('<urllib3.connection.HTTPConnection object at 0x00000235FC0259C0>: Failed to establish a new connection: [Errno 11001] getaddrinfo failed')': /
2023-04-16 19:13:44,624 - connectionpool.py[line:812] - WARNING: Retrying (Retry(total=0, connect=None, read=None, redirect=None, status=None)) after connection broken by 'NewConnectionError('<urllib3.connection.HTTPConnection object at 0x00000235FC025B10>: Failed to establish a new connection: [Errno 11001] getaddrinfo failed')': /
